2023-09-19 16:04:28,883 ERROR: Exception on /index [GET] [in C:\Users\YiyoZapata\miniconda3\Lib\site-packages\flask\app.py:1414]
Traceback (most recent call last):
  File "C:\Users\YiyoZapata\miniconda3\Lib\site-packages\flask\app.py", line 2190, in wsgi_app
    response = self.full_dispatch_request()
               ^^^^^^^^^^^^^^^^^^^^^^^^^^^^
  File "C:\Users\YiyoZapata\miniconda3\Lib\site-packages\flask\app.py", line 1486, in full_dispatch_request
    rv = self.handle_user_exception(e)
         ^^^^^^^^^^^^^^^^^^^^^^^^^^^^^
  File "C:\Users\YiyoZapata\miniconda3\Lib\site-packages\flask\app.py", line 1482, in full_dispatch_request
    rv = self.preprocess_request()
         ^^^^^^^^^^^^^^^^^^^^^^^^^
  File "C:\Users\YiyoZapata\miniconda3\Lib\site-packages\flask\app.py", line 1974, in preprocess_request
    rv = self.ensure_sync(before_func)()
         ^^^^^^^^^^^^^^^^^^^^^^^^^^^^^^^
  File "C:\Users\YiyoZapata\Desktop\mongo_flask\microblog\app\main\routes.py", line 19, in before_request
    if current_user.is_authenticated:
       ^^^^^^^^^^^^^^^^^^^^^^^^^^^^^
  File "C:\Users\YiyoZapata\miniconda3\Lib\site-packages\werkzeug\local.py", line 311, in __get__
    obj = instance._get_current_object()
          ^^^^^^^^^^^^^^^^^^^^^^^^^^^^^^
  File "C:\Users\YiyoZapata\miniconda3\Lib\site-packages\werkzeug\local.py", line 515, in _get_current_object
    return get_name(local())
                    ^^^^^^^
  File "C:\Users\YiyoZapata\miniconda3\Lib\site-packages\flask_login\utils.py", line 25, in <lambda>
    current_user = LocalProxy(lambda: _get_user())
                                      ^^^^^^^^^^^
  File "C:\Users\YiyoZapata\miniconda3\Lib\site-packages\flask_login\utils.py", line 372, in _get_user
    current_app.login_manager._load_user()
  File "C:\Users\YiyoZapata\miniconda3\Lib\site-packages\flask_login\login_manager.py", line 364, in _load_user
    user = self._user_callback(user_id)
           ^^^^^^^^^^^^^^^^^^^^^^^^^^^^
  File "C:\Users\YiyoZapata\Desktop\mongo_flask\microblog\app\models.py", line 147, in load_user
    from app import mongo
ImportError: cannot import name 'mongo' from 'app' (C:\Users\YiyoZapata\Desktop\mongo_flask\microblog\app\__init__.py)
2023-09-19 16:05:49,036 ERROR: Exception on /index [GET] [in C:\Users\YiyoZapata\miniconda3\Lib\site-packages\flask\app.py:1414]
Traceback (most recent call last):
  File "C:\Users\YiyoZapata\miniconda3\Lib\site-packages\flask\app.py", line 2190, in wsgi_app
    response = self.full_dispatch_request()
               ^^^^^^^^^^^^^^^^^^^^^^^^^^^^
  File "C:\Users\YiyoZapata\miniconda3\Lib\site-packages\flask\app.py", line 1486, in full_dispatch_request
    rv = self.handle_user_exception(e)
         ^^^^^^^^^^^^^^^^^^^^^^^^^^^^^
  File "C:\Users\YiyoZapata\miniconda3\Lib\site-packages\flask\app.py", line 1482, in full_dispatch_request
    rv = self.preprocess_request()
         ^^^^^^^^^^^^^^^^^^^^^^^^^
  File "C:\Users\YiyoZapata\miniconda3\Lib\site-packages\flask\app.py", line 1974, in preprocess_request
    rv = self.ensure_sync(before_func)()
         ^^^^^^^^^^^^^^^^^^^^^^^^^^^^^^^
  File "C:\Users\YiyoZapata\Desktop\mongo_flask\microblog\app\main\routes.py", line 19, in before_request
    if current_user.is_authenticated:
       ^^^^^^^^^^^^^^^^^^^^^^^^^^^^^
  File "C:\Users\YiyoZapata\miniconda3\Lib\site-packages\werkzeug\local.py", line 311, in __get__
    obj = instance._get_current_object()
          ^^^^^^^^^^^^^^^^^^^^^^^^^^^^^^
  File "C:\Users\YiyoZapata\miniconda3\Lib\site-packages\werkzeug\local.py", line 515, in _get_current_object
    return get_name(local())
                    ^^^^^^^
  File "C:\Users\YiyoZapata\miniconda3\Lib\site-packages\flask_login\utils.py", line 25, in <lambda>
    current_user = LocalProxy(lambda: _get_user())
                                      ^^^^^^^^^^^
  File "C:\Users\YiyoZapata\miniconda3\Lib\site-packages\flask_login\utils.py", line 372, in _get_user
    current_app.login_manager._load_user()
  File "C:\Users\YiyoZapata\miniconda3\Lib\site-packages\flask_login\login_manager.py", line 364, in _load_user
    user = self._user_callback(user_id)
           ^^^^^^^^^^^^^^^^^^^^^^^^^^^^
  File "C:\Users\YiyoZapata\Desktop\mongo_flask\microblog\app\models.py", line 147, in load_user
    from app import mongo
ImportError: cannot import name 'mongo' from 'app' (C:\Users\YiyoZapata\Desktop\mongo_flask\microblog\app\__init__.py)
2023-09-19 16:05:52,866 ERROR: Exception on /index [GET] [in C:\Users\YiyoZapata\miniconda3\Lib\site-packages\flask\app.py:1414]
Traceback (most recent call last):
  File "C:\Users\YiyoZapata\miniconda3\Lib\site-packages\flask\app.py", line 2190, in wsgi_app
    response = self.full_dispatch_request()
               ^^^^^^^^^^^^^^^^^^^^^^^^^^^^
  File "C:\Users\YiyoZapata\miniconda3\Lib\site-packages\flask\app.py", line 1486, in full_dispatch_request
    rv = self.handle_user_exception(e)
         ^^^^^^^^^^^^^^^^^^^^^^^^^^^^^
  File "C:\Users\YiyoZapata\miniconda3\Lib\site-packages\flask\app.py", line 1482, in full_dispatch_request
    rv = self.preprocess_request()
         ^^^^^^^^^^^^^^^^^^^^^^^^^
  File "C:\Users\YiyoZapata\miniconda3\Lib\site-packages\flask\app.py", line 1974, in preprocess_request
    rv = self.ensure_sync(before_func)()
         ^^^^^^^^^^^^^^^^^^^^^^^^^^^^^^^
  File "C:\Users\YiyoZapata\Desktop\mongo_flask\microblog\app\main\routes.py", line 19, in before_request
    if current_user.is_authenticated:
       ^^^^^^^^^^^^^^^^^^^^^^^^^^^^^
  File "C:\Users\YiyoZapata\miniconda3\Lib\site-packages\werkzeug\local.py", line 311, in __get__
    obj = instance._get_current_object()
          ^^^^^^^^^^^^^^^^^^^^^^^^^^^^^^
  File "C:\Users\YiyoZapata\miniconda3\Lib\site-packages\werkzeug\local.py", line 515, in _get_current_object
    return get_name(local())
                    ^^^^^^^
  File "C:\Users\YiyoZapata\miniconda3\Lib\site-packages\flask_login\utils.py", line 25, in <lambda>
    current_user = LocalProxy(lambda: _get_user())
                                      ^^^^^^^^^^^
  File "C:\Users\YiyoZapata\miniconda3\Lib\site-packages\flask_login\utils.py", line 372, in _get_user
    current_app.login_manager._load_user()
  File "C:\Users\YiyoZapata\miniconda3\Lib\site-packages\flask_login\login_manager.py", line 364, in _load_user
    user = self._user_callback(user_id)
           ^^^^^^^^^^^^^^^^^^^^^^^^^^^^
  File "C:\Users\YiyoZapata\Desktop\mongo_flask\microblog\app\models.py", line 147, in load_user
    from app import mongo
ImportError: cannot import name 'mongo' from 'app' (C:\Users\YiyoZapata\Desktop\mongo_flask\microblog\app\__init__.py)
2023-09-21 14:22:57,428 INFO: Microblog startup [in C:\Users\YiyoZapata\Desktop\mongo_flask\microblog\app\__init__.py:80]
2023-09-21 14:27:53,362 ERROR: Exception on /unfollow/susan [POST] [in C:\Users\YiyoZapata\Desktop\mongo_flask\microblog\venv\Lib\site-packages\flask\app.py:1414]
Traceback (most recent call last):
  File "C:\Users\YiyoZapata\Desktop\mongo_flask\microblog\venv\Lib\site-packages\flask\app.py", line 2190, in wsgi_app
    response = self.full_dispatch_request()
               ^^^^^^^^^^^^^^^^^^^^^^^^^^^^
  File "C:\Users\YiyoZapata\Desktop\mongo_flask\microblog\venv\Lib\site-packages\flask\app.py", line 1486, in full_dispatch_request
    rv = self.handle_user_exception(e)
         ^^^^^^^^^^^^^^^^^^^^^^^^^^^^^
  File "C:\Users\YiyoZapata\Desktop\mongo_flask\microblog\venv\Lib\site-packages\flask\app.py", line 1484, in full_dispatch_request
    rv = self.dispatch_request()
         ^^^^^^^^^^^^^^^^^^^^^^^
  File "C:\Users\YiyoZapata\Desktop\mongo_flask\microblog\venv\Lib\site-packages\flask\app.py", line 1469, in dispatch_request
    return self.ensure_sync(self.view_functions[rule.endpoint])(**view_args)
           ^^^^^^^^^^^^^^^^^^^^^^^^^^^^^^^^^^^^^^^^^^^^^^^^^^^^^^^^^^^^^^^^^
  File "C:\Users\YiyoZapata\Desktop\mongo_flask\microblog\venv\Lib\site-packages\flask_login\utils.py", line 290, in decorated_view
    return current_app.ensure_sync(func)(*args, **kwargs)
           ^^^^^^^^^^^^^^^^^^^^^^^^^^^^^^^^^^^^^^^^^^^^^^
  File "C:\Users\YiyoZapata\Desktop\mongo_flask\microblog\app\main\routes.py", line 255, in unfollow
    user_to_unfollow.followers.remove(current_user._id)  # Elimina el seguidor del usuario que está siendo dejado de seguir
    ^^^^^^^^^^^^^^^^^^^^^^^^^^^^^^^^^^^^^^^^^^^^^^^^^^^
ValueError: list.remove(x): x not in list
2023-09-21 14:28:57,717 ERROR: Exception on /unfollow/susan [POST] [in C:\Users\YiyoZapata\Desktop\mongo_flask\microblog\venv\Lib\site-packages\flask\app.py:1414]
Traceback (most recent call last):
  File "C:\Users\YiyoZapata\Desktop\mongo_flask\microblog\venv\Lib\site-packages\flask\app.py", line 2190, in wsgi_app
    response = self.full_dispatch_request()
               ^^^^^^^^^^^^^^^^^^^^^^^^^^^^
  File "C:\Users\YiyoZapata\Desktop\mongo_flask\microblog\venv\Lib\site-packages\flask\app.py", line 1486, in full_dispatch_request
    rv = self.handle_user_exception(e)
         ^^^^^^^^^^^^^^^^^^^^^^^^^^^^^
  File "C:\Users\YiyoZapata\Desktop\mongo_flask\microblog\venv\Lib\site-packages\flask\app.py", line 1484, in full_dispatch_request
    rv = self.dispatch_request()
         ^^^^^^^^^^^^^^^^^^^^^^^
  File "C:\Users\YiyoZapata\Desktop\mongo_flask\microblog\venv\Lib\site-packages\flask\app.py", line 1469, in dispatch_request
    return self.ensure_sync(self.view_functions[rule.endpoint])(**view_args)
           ^^^^^^^^^^^^^^^^^^^^^^^^^^^^^^^^^^^^^^^^^^^^^^^^^^^^^^^^^^^^^^^^^
  File "C:\Users\YiyoZapata\Desktop\mongo_flask\microblog\venv\Lib\site-packages\flask_login\utils.py", line 290, in decorated_view
    return current_app.ensure_sync(func)(*args, **kwargs)
           ^^^^^^^^^^^^^^^^^^^^^^^^^^^^^^^^^^^^^^^^^^^^^^
  File "C:\Users\YiyoZapata\Desktop\mongo_flask\microblog\app\main\routes.py", line 255, in unfollow
    user_to_unfollow.followers.remove(current_user._id)  # Elimina el seguidor del usuario que está siendo dejado de seguir
    ^^^^^^^^^^^^^^^^^^^^^^^^^^^^^^^^^^^^^^^^^^^^^^^^^^^
ValueError: list.remove(x): x not in list
