2023-09-12 11:41:02,261 ERROR: Exception on /follow/yiyo [POST] [in C:\Users\YiyoZapata\Desktop\mongo_flask\microblog\venv\Lib\site-packages\flask\app.py:1414]
Traceback (most recent call last):
  File "C:\Users\YiyoZapata\Desktop\mongo_flask\microblog\venv\Lib\site-packages\flask\app.py", line 2190, in wsgi_app
    response = self.full_dispatch_request()
               ^^^^^^^^^^^^^^^^^^^^^^^^^^^^
  File "C:\Users\YiyoZapata\Desktop\mongo_flask\microblog\venv\Lib\site-packages\flask\app.py", line 1486, in full_dispatch_request
    rv = self.handle_user_exception(e)
         ^^^^^^^^^^^^^^^^^^^^^^^^^^^^^
  File "C:\Users\YiyoZapata\Desktop\mongo_flask\microblog\venv\Lib\site-packages\flask\app.py", line 1484, in full_dispatch_request
    rv = self.dispatch_request()
         ^^^^^^^^^^^^^^^^^^^^^^^
  File "C:\Users\YiyoZapata\Desktop\mongo_flask\microblog\venv\Lib\site-packages\flask\app.py", line 1469, in dispatch_request
    return self.ensure_sync(self.view_functions[rule.endpoint])(**view_args)
           ^^^^^^^^^^^^^^^^^^^^^^^^^^^^^^^^^^^^^^^^^^^^^^^^^^^^^^^^^^^^^^^^^
  File "C:\Users\YiyoZapata\Desktop\mongo_flask\microblog\venv\Lib\site-packages\flask_login\utils.py", line 290, in decorated_view
    return current_app.ensure_sync(func)(*args, **kwargs)
           ^^^^^^^^^^^^^^^^^^^^^^^^^^^^^^^^^^^^^^^^^^^^^^
  File "C:\Users\YiyoZapata\Desktop\mongo_flask\microblog\app\routes.py", line 264, in follow
    current_user.save()  # Guardar los cambios en el usuario actual
    ^^^^^^^^^^^^^^^^^^^
  File "C:\Users\YiyoZapata\Desktop\mongo_flask\microblog\app\models.py", line 33, in save
    self.id = users_collection.insert_one(self.__dict__).inserted_id
              ^^^^^^^^^^^^^^^^^^^^^^^^^^^^^^^^^^^^^^^^^^
  File "C:\Users\YiyoZapata\Desktop\mongo_flask\microblog\venv\Lib\site-packages\pymongo\collection.py", line 671, in insert_one
    self._insert_one(
  File "C:\Users\YiyoZapata\Desktop\mongo_flask\microblog\venv\Lib\site-packages\pymongo\collection.py", line 611, in _insert_one
    self.__database.client._retryable_write(acknowledged, _insert_command, session)
  File "C:\Users\YiyoZapata\Desktop\mongo_flask\microblog\venv\Lib\site-packages\pymongo\mongo_client.py", line 1568, in _retryable_write
    return self._retry_with_session(retryable, func, s, None)
           ^^^^^^^^^^^^^^^^^^^^^^^^^^^^^^^^^^^^^^^^^^^^^^^^^^
  File "C:\Users\YiyoZapata\Desktop\mongo_flask\microblog\venv\Lib\site-packages\pymongo\mongo_client.py", line 1413, in _retry_with_session
    return self._retry_internal(retryable, func, session, bulk)
           ^^^^^^^^^^^^^^^^^^^^^^^^^^^^^^^^^^^^^^^^^^^^^^^^^^^^
  File "C:\Users\YiyoZapata\Desktop\mongo_flask\microblog\venv\Lib\site-packages\pymongo\_csot.py", line 108, in csot_wrapper
    return func(self, *args, **kwargs)
           ^^^^^^^^^^^^^^^^^^^^^^^^^^^
  File "C:\Users\YiyoZapata\Desktop\mongo_flask\microblog\venv\Lib\site-packages\pymongo\mongo_client.py", line 1460, in _retry_internal
    return func(session, conn, retryable)
           ^^^^^^^^^^^^^^^^^^^^^^^^^^^^^^
  File "C:\Users\YiyoZapata\Desktop\mongo_flask\microblog\venv\Lib\site-packages\pymongo\collection.py", line 609, in _insert_command
    _check_write_command_response(result)
  File "C:\Users\YiyoZapata\Desktop\mongo_flask\microblog\venv\Lib\site-packages\pymongo\helpers.py", line 259, in _check_write_command_response
    _raise_last_write_error(write_errors)
  File "C:\Users\YiyoZapata\Desktop\mongo_flask\microblog\venv\Lib\site-packages\pymongo\helpers.py", line 231, in _raise_last_write_error
    raise DuplicateKeyError(error.get("errmsg"), 11000, error)
pymongo.errors.DuplicateKeyError: E11000 duplicate key error collection: db.users index: _id_ dup key: { _id: "6500320aebf35759c3368766" }, full error: {'index': 0, 'code': 11000, 'errmsg': 'E11000 duplicate key error collection: db.users index: _id_ dup key: { _id: "6500320aebf35759c3368766" }', 'keyPattern': {'_id': 1}, 'keyValue': {'_id': '6500320aebf35759c3368766'}}
2023-09-12 11:41:41,844 ERROR: Exception on /follow/rodri [POST] [in C:\Users\YiyoZapata\Desktop\mongo_flask\microblog\venv\Lib\site-packages\flask\app.py:1414]
Traceback (most recent call last):
  File "C:\Users\YiyoZapata\Desktop\mongo_flask\microblog\venv\Lib\site-packages\flask\app.py", line 2190, in wsgi_app
    response = self.full_dispatch_request()
               ^^^^^^^^^^^^^^^^^^^^^^^^^^^^
  File "C:\Users\YiyoZapata\Desktop\mongo_flask\microblog\venv\Lib\site-packages\flask\app.py", line 1486, in full_dispatch_request
    rv = self.handle_user_exception(e)
         ^^^^^^^^^^^^^^^^^^^^^^^^^^^^^
  File "C:\Users\YiyoZapata\Desktop\mongo_flask\microblog\venv\Lib\site-packages\flask\app.py", line 1484, in full_dispatch_request
    rv = self.dispatch_request()
         ^^^^^^^^^^^^^^^^^^^^^^^
  File "C:\Users\YiyoZapata\Desktop\mongo_flask\microblog\venv\Lib\site-packages\flask\app.py", line 1469, in dispatch_request
    return self.ensure_sync(self.view_functions[rule.endpoint])(**view_args)
           ^^^^^^^^^^^^^^^^^^^^^^^^^^^^^^^^^^^^^^^^^^^^^^^^^^^^^^^^^^^^^^^^^
  File "C:\Users\YiyoZapata\Desktop\mongo_flask\microblog\venv\Lib\site-packages\flask_login\utils.py", line 290, in decorated_view
    return current_app.ensure_sync(func)(*args, **kwargs)
           ^^^^^^^^^^^^^^^^^^^^^^^^^^^^^^^^^^^^^^^^^^^^^^
  File "C:\Users\YiyoZapata\Desktop\mongo_flask\microblog\app\routes.py", line 264, in follow
    current_user.save()  # Guardar los cambios en el usuario actual
    ^^^^^^^^^^^^^^^^^^^
  File "C:\Users\YiyoZapata\Desktop\mongo_flask\microblog\app\models.py", line 33, in save
    self.id = users_collection.insert_one(self.__dict__).inserted_id
              ^^^^^^^^^^^^^^^^^^^^^^^^^^^^^^^^^^^^^^^^^^
  File "C:\Users\YiyoZapata\Desktop\mongo_flask\microblog\venv\Lib\site-packages\pymongo\collection.py", line 671, in insert_one
    self._insert_one(
  File "C:\Users\YiyoZapata\Desktop\mongo_flask\microblog\venv\Lib\site-packages\pymongo\collection.py", line 611, in _insert_one
    self.__database.client._retryable_write(acknowledged, _insert_command, session)
  File "C:\Users\YiyoZapata\Desktop\mongo_flask\microblog\venv\Lib\site-packages\pymongo\mongo_client.py", line 1568, in _retryable_write
    return self._retry_with_session(retryable, func, s, None)
           ^^^^^^^^^^^^^^^^^^^^^^^^^^^^^^^^^^^^^^^^^^^^^^^^^^
  File "C:\Users\YiyoZapata\Desktop\mongo_flask\microblog\venv\Lib\site-packages\pymongo\mongo_client.py", line 1413, in _retry_with_session
    return self._retry_internal(retryable, func, session, bulk)
           ^^^^^^^^^^^^^^^^^^^^^^^^^^^^^^^^^^^^^^^^^^^^^^^^^^^^
  File "C:\Users\YiyoZapata\Desktop\mongo_flask\microblog\venv\Lib\site-packages\pymongo\_csot.py", line 108, in csot_wrapper
    return func(self, *args, **kwargs)
           ^^^^^^^^^^^^^^^^^^^^^^^^^^^
  File "C:\Users\YiyoZapata\Desktop\mongo_flask\microblog\venv\Lib\site-packages\pymongo\mongo_client.py", line 1460, in _retry_internal
    return func(session, conn, retryable)
           ^^^^^^^^^^^^^^^^^^^^^^^^^^^^^^
  File "C:\Users\YiyoZapata\Desktop\mongo_flask\microblog\venv\Lib\site-packages\pymongo\collection.py", line 609, in _insert_command
    _check_write_command_response(result)
  File "C:\Users\YiyoZapata\Desktop\mongo_flask\microblog\venv\Lib\site-packages\pymongo\helpers.py", line 259, in _check_write_command_response
    _raise_last_write_error(write_errors)
  File "C:\Users\YiyoZapata\Desktop\mongo_flask\microblog\venv\Lib\site-packages\pymongo\helpers.py", line 231, in _raise_last_write_error
    raise DuplicateKeyError(error.get("errmsg"), 11000, error)
pymongo.errors.DuplicateKeyError: E11000 duplicate key error collection: db.users index: _id_ dup key: { _id: "6500320aebf35759c3368766" }, full error: {'index': 0, 'code': 11000, 'errmsg': 'E11000 duplicate key error collection: db.users index: _id_ dup key: { _id: "6500320aebf35759c3368766" }', 'keyPattern': {'_id': 1}, 'keyValue': {'_id': '6500320aebf35759c3368766'}}
2023-09-12 11:48:08,240 INFO: Microblog startup [in C:\Users\YiyoZapata\Desktop\mongo_flask\microblog\app\__init__.py:49]
2023-09-12 11:53:02,009 INFO: Microblog startup [in C:\Users\YiyoZapata\Desktop\mongo_flask\microblog\app\__init__.py:49]
2023-09-12 11:53:05,406 ERROR: Exception on /unfollow/yiyo [POST] [in C:\Users\YiyoZapata\Desktop\mongo_flask\microblog\venv\Lib\site-packages\flask\app.py:1414]
Traceback (most recent call last):
  File "C:\Users\YiyoZapata\Desktop\mongo_flask\microblog\venv\Lib\site-packages\flask\app.py", line 2190, in wsgi_app
    response = self.full_dispatch_request()
               ^^^^^^^^^^^^^^^^^^^^^^^^^^^^
  File "C:\Users\YiyoZapata\Desktop\mongo_flask\microblog\venv\Lib\site-packages\flask\app.py", line 1486, in full_dispatch_request
    rv = self.handle_user_exception(e)
         ^^^^^^^^^^^^^^^^^^^^^^^^^^^^^
  File "C:\Users\YiyoZapata\Desktop\mongo_flask\microblog\venv\Lib\site-packages\flask\app.py", line 1484, in full_dispatch_request
    rv = self.dispatch_request()
         ^^^^^^^^^^^^^^^^^^^^^^^
  File "C:\Users\YiyoZapata\Desktop\mongo_flask\microblog\venv\Lib\site-packages\flask\app.py", line 1469, in dispatch_request
    return self.ensure_sync(self.view_functions[rule.endpoint])(**view_args)
           ^^^^^^^^^^^^^^^^^^^^^^^^^^^^^^^^^^^^^^^^^^^^^^^^^^^^^^^^^^^^^^^^^
  File "C:\Users\YiyoZapata\Desktop\mongo_flask\microblog\venv\Lib\site-packages\flask_login\utils.py", line 290, in decorated_view
    return current_app.ensure_sync(func)(*args, **kwargs)
           ^^^^^^^^^^^^^^^^^^^^^^^^^^^^^^^^^^^^^^^^^^^^^^
  File "C:\Users\YiyoZapata\Desktop\mongo_flask\microblog\app\routes.py", line 284, in unfollow
    current_user.update()  # Guardar los cambios en el usuario actual
    ^^^^^^^^^^^^^^^^^^^^^
TypeError: User.update() missing 1 required positional argument: 'update_values'
